Traceback (most recent call last):
  File "./acceptance.py", line 31, in test_add_contact
    self.assertIn('Add Contact', self.driver.title)
AssertionError: 'Add Contact' not found in 'TemplateDoesNotExist at /new'

----------------------------------------------------------------------
Ran 2 tests in 11.912s


ERROR: test_add_contact (__main__.IntergrationTests)
----------------------------------------------------------------------
Traceback (most recent call last):
  File "./acceptance.py", line 32, in test_add_contact
    self.driver.find_element_by_link_text('add contact').click()
  File "/home/hamub/.virtualenvs/tdd/lib/python3.5/site-packages/selenium/webdriver/remote/webdriver.py", line 317, in find_element_by_link_text
    return self.find_element(by=By.LINK_TEXT, value=link_text)
  File "/home/hamub/.virtualenvs/tdd/lib/python3.5/site-packages/selenium/webdriver/remote/webdriver.py", line 745, in find_element
    {'using': by, 'value': value})['value']
  File "/home/hamub/.virtualenvs/tdd/lib/python3.5/site-packages/selenium/webdriver/remote/webdriver.py", line 236, in execute
    self.error_handler.check_response(response)
  File "/home/hamub/.virtualenvs/tdd/lib/python3.5/site-packages/selenium/webdriver/remote/errorhandler.py", line 194, in check_response
    raise exception_class(message, screen, stacktrace)
selenium.common.exceptions.NoSuchElementException: Message: no such element
  (Session info: chrome=52.0.2743.116)
  (Driver info: chromedriver=2.9.248304,platform=Linux 4.4.0-36-generic x86_64)


----------------------------------------------------------------------
Ran 2 tests in 10.492s

FAILED (errors=1)

